Workbook

Sheet Inputs
B2: Inputs and scenario drivers
B3: Demo Co. (synthetic) · $mm · Source: SYNTHETIC DEMO DATA
B5: Active scenario (1 = Base, 2 = Upside, 3 = Downside) | C5: 1 | D5: =CHOOSE($C$5,"Base","Upside","Downside") -> Base
B8: Operating drivers | C8: FY23A | D8: FY24A | E8: FY25A | F8: FY26E | G8: FY27E | H8: FY28E | I8: FY29E | J8: FY30E
B9: Revenue growth
B10: Base | F10: 0.05 | G10: 0.05 | H10: 0.045 | I10: 0.04 | J10: 0.035
B11: Upside | F11: 0.08 | G11: 0.075 | H11: 0.065 | I11: 0.055 | J11: 0.045
B12: Downside | F12: -0.04 | G12: 0 | H12: 0.02 | I12: 0.025 | J12: 0.03
B13: ► Live case | F13: =CHOOSE(Inputs!$C$5,F10,F11,F12) -> 0.05 | G13: =CHOOSE(Inputs!$C$5,G10,G11,G12) -> 0.05 | H13: =CHOOSE(Inputs!$C$5,H10,H11,H12) -> 0.045 | I13: =CHOOSE(Inputs!$C$5,I10,I11,I12) -> 0.04 | J13: =CHOOSE(Inputs!$C$5,J10,J11,J12) -> 0.035
B15: COGS % of revenue
B16: Base | F16: 0.575 | G16: 0.575 | H16: 0.575 | I16: 0.575 | J16: 0.575
B17: Upside | F17: 0.57 | G17: 0.57 | H17: 0.57 | I17: 0.57 | J17: 0.57
B18: Downside | F18: 0.595 | G18: 0.595 | H18: 0.595 | I18: 0.595 | J18: 0.595
B19: ► Live case | F19: =CHOOSE(Inputs!$C$5,F16,F17,F18) -> 0.575 | G19: =CHOOSE(Inputs!$C$5,G16,G17,G18) -> 0.575 | H19: =CHOOSE(Inputs!$C$5,H16,H17,H18) -> 0.575 | I19: =CHOOSE(Inputs!$C$5,I16,I17,I18) -> 0.575 | J19: =CHOOSE(Inputs!$C$5,J16,J17,J18) -> 0.575
B21: SG&A % of revenue
B22: Base | F22: 0.235 | G22: 0.235 | H22: 0.235 | I22: 0.235 | J22: 0.235
B23: Upside | F23: 0.23 | G23: 0.23 | H23: 0.23 | I23: 0.23 | J23: 0.23
B24: Downside | F24: 0.25 | G24: 0.25 | H24: 0.25 | I24: 0.25 | J24: 0.25
B25: ► Live case | F25: =CHOOSE(Inputs!$C$5,F22,F23,F24) -> 0.235 | G25: =CHOOSE(Inputs!$C$5,G22,G23,G24) -> 0.235 | H25: =CHOOSE(Inputs!$C$5,H22,H23,H24) -> 0.235 | I25: =CHOOSE(Inputs!$C$5,I22,I23,I24) -> 0.235 | J25: =CHOOSE(Inputs!$C$5,J22,J23,J24) -> 0.235
B27: Days sales outstanding
B28: Base | F28: 48 | G28: 48 | H28: 48 | I28: 48 | J28: 48
B29: Upside | F29: 46 | G29: 46 | H29: 46 | I29: 46 | J29: 46
B30: Downside | F30: 53 | G30: 53 | H30: 53 | I30: 53 | J30: 53
B31: ► Live case | F31: =CHOOSE(Inputs!$C$5,F28,F29,F30) -> 48 | G31: =CHOOSE(Inputs!$C$5,G28,G29,G30) -> 48 | H31: =CHOOSE(Inputs!$C$5,H28,H29,H30) -> 48 | I31: =CHOOSE(Inputs!$C$5,I28,I29,I30) -> 48 | J31: =CHOOSE(Inputs!$C$5,J28,J29,J30) -> 48
B33: Days inventory (on COGS)
B34: Base | F34: 74 | G34: 74 | H34: 74 | I34: 74 | J34: 74
B35: Upside | F35: 70 | G35: 70 | H35: 70 | I35: 70 | J35: 70
B36: Downside | F36: 80 | G36: 80 | H36: 80 | I36: 80 | J36: 80
B37: ► Live case | F37: =CHOOSE(Inputs!$C$5,F34,F35,F36) -> 74 | G37: =CHOOSE(Inputs!$C$5,G34,G35,G36) -> 74 | H37: =CHOOSE(Inputs!$C$5,H34,H35,H36) -> 74 | I37: =CHOOSE(Inputs!$C$5,I34,I35,I36) -> 74 | J37: =CHOOSE(Inputs!$C$5,J34,J35,J36) -> 74
B39: Days payables (on COGS)
B40: Base | F40: 51 | G40: 51 | H40: 51 | I40: 51 | J40: 51
B41: Upside | F41: 53 | G41: 53 | H41: 53 | I41: 53 | J41: 53
B42: Downside | F42: 47 | G42: 47 | H42: 47 | I42: 47 | J42: 47
B43: ► Live case | F43: =CHOOSE(Inputs!$C$5,F40,F41,F42) -> 51 | G43: =CHOOSE(Inputs!$C$5,G40,G41,G42) -> 51 | H43: =CHOOSE(Inputs!$C$5,H40,H41,H42) -> 51 | I43: =CHOOSE(Inputs!$C$5,I40,I41,I42) -> 51 | J43: =CHOOSE(Inputs!$C$5,J40,J41,J42) -> 51
B45: Financing and policy (all scenarios)
B46: Tax rate | C46: 0.24
B47: Interest rate, term debt | C47: 0.06
B48: Interest rate, revolver | C48: 0.07
B49: Interest income on cash | C49: 0.03
B50: Minimum cash balance | C50: 250
...

Sheet Income Statement
B2: Income statement
B3: Demo Co. (synthetic) · $mm · Source: SYNTHETIC DEMO DATA
C6: FY23A | D6: FY24A | E6: FY25A | F6: FY26E | G6: FY27E | H6: FY28E | I6: FY29E | J6: FY30E
B7: Revenue | C7: 4200 | D7: 4480 | E7: 4750 | F7: =E7*(1+Inputs!F$13) -> 4987.5 | G7: =F7*(1+Inputs!G$13) -> 5236.875 | H7: =G7*(1+Inputs!H$13) -> 5472.5344 | I7: =H7*(1+Inputs!I$13) -> 5691.4357 | J7: =I7*(1+Inputs!J$13) -> 5890.636
B8: COGS | C8: 2457 | D8: 2598.4 | E8: 2745.5 | F8: =F7*Inputs!F$19 -> 2867.8125 | G8: =G7*Inputs!G$19 -> 3011.2031 | H8: =H7*Inputs!H$19 -> 3146.7073 | I8: =I7*Inputs!I$19 -> 3272.5756 | J8: =J7*Inputs!J$19 -> 3387.1157
B9: Gross profit | C9: =C7-C8 -> 1743 | D9: =D7-D8 -> 1881.6 | E9: =E7-E8 -> 2004.5 | F9: =F7-F8 -> 2119.6875 | G9: =G7-G8 -> 2225.6719 | H9: =H7-H8 -> 2325.8271 | I9: =I7-I8 -> 2418.8602 | J9: =J7-J8 -> 2503.5203
B10: SG&A | C10: 1008 | D10: 1066.24 | E10: 1121 | F10: =F7*Inputs!F$25 -> 1172.0625 | G10: =G7*Inputs!G$25 -> 1230.6656 | H10: =H7*Inputs!H$25 -> 1286.0456 | I10: =I7*Inputs!I$25 -> 1337.4874 | J10: =J7*Inputs!J$25 -> 1384.2995
B11: EBITDA | C11: =C9-C10 -> 735 | D11: =D9-D10 -> 815.36 | E11: =E9-E10 -> 883.5 | F11: =F9-F10 -> 947.625 | G11: =G9-G10 -> 995.00625 | H11: =H9-H10 -> 1039.7815 | I11: =I9-I10 -> 1081.3728 | J11: =J9-J10 -> 1119.2208
B12: D&A | C12: 147 | D12: 156.8 | E12: 166.25 | F12: =F7*Inputs!$C$53 -> 179.55 | G12: =G7*Inputs!$C$53 -> 188.5275 | H12: =H7*Inputs!$C$53 -> 197.01124 | I12: =I7*Inputs!$C$53 -> 204.89169 | J12: =J7*Inputs!$C$53 -> 212.0629
B13: EBIT | C13: =C11-C12 -> 588 | D13: =D11-D12 -> 658.56 | E13: =E11-E12 -> 717.25 | F13: =F11-F12 -> 768.075 | G13: =G11-G12 -> 806.47875 | H13: =H11-H12 -> 842.77029 | I13: =I11-I12 -> 876.48111 | J13: =J11-J12 -> 907.15794
B14: Interest expense | C14: 126 | D14: 123 | E14: 118 | F14: ='Balance Sheet'!E18*Inputs!$C$47+'Balance Sheet'!E17*Inputs!$C$48 -> 114 | G14: ='Balance Sheet'!F18*Inputs!$C$47+'Balance Sheet'!F17*Inputs!$C$48 -> 105 | H14: ='Balance Sheet'!G18*Inputs!$C$47+'Balance Sheet'!G17*Inputs!$C$48 -> 96 | I14: ='Balance Sheet'!H18*Inputs!$C$47+'Balance Sheet'!H17*Inputs!$C$48 -> 87 | J14: ='Balance Sheet'!I18*Inputs!$C$47+'Balance Sheet'!I17*Inputs!$C$48 -> 78
B15: Interest income | C15: 6 | D15: 7 | E15: 8 | F15: ='Balance Sheet'!E7*Inputs!$C$49 -> 9 | G15: ='Balance Sheet'!F7*Inputs!$C$49 -> 12.673428 | H15: ='Balance Sheet'!G7*Inputs!$C$49 -> 17.287239 | I15: ='Balance Sheet'!H7*Inputs!$C$49 -> 23.044283 | J15: ='Balance Sheet'!I7*Inputs!$C$49 -> 29.931621
B16: EBT | C16: =C13-C14+C15 -> 468 | D16: =D13-D14+D15 -> 542.56 | E16: =E13-E14+E15 -> 607.25 | F16: =F13-F14+F15 -> 663.075 | G16: =G13-G14+G15 -> 714.15218 | H16: =H13-H14+H15 -> 764.05753 | I16: =I13-I14+I15 -> 812.52539 | J16: =J13-J14+J15 -> 859.08957
B17: Tax | C17: 112.32 | D17: 130.2144 | E17: 145.74 | F17: =MAX(0,F16)*Inputs!$C$46 -> 159.138 | G17: =MAX(0,G16)*Inputs!$C$46 -> 171.39652 | H17: =MAX(0,H16)*Inputs!$C$46 -> 183.37381 | I17: =MAX(0,I16)*Inputs!$C$46 -> 195.00609 | J17: =MAX(0,J16)*Inputs!$C$46 -> 206.1815
B18: Net income | C18: =C16-C17 -> 355.68 | D18: =D16-D17 -> 412.3456 | E18: =E16-E17 -> 461.51 | F18: =F16-F17 -> 503.937 | G18: =G16-G17 -> 542.75566 | H18: =H16-H17 -> 580.68372 | I18: =I16-I17 -> 617.5193 | J18: =J16-J17 -> 652.90807
B20: EBITDA margin | C20: =C11/C7 -> 0.175 | D20: =D11/D7 -> 0.182 | E20: =E11/E7 -> 0.186 | F20: =F11/F7 -> 0.19 | G20: =G11/G7 -> 0.19 | H20: =H11/H7 -> 0.19 | I20: =I11/I7 -> 0.19 | J20: =J11/J7 -> 0.19
B21: Revenue growth | D21: =D7/C7-1 -> 0.066666667 | E21: =E7/D7-1 -> 0.060267857 | F21: =F7/E7-1 -> 0.05 | G21: =G7/F7-1 -> 0.05 | H21: =H7/G7-1 -> 0.045 | I21: =I7/H7-1 -> 0.04 | J21: =J7/I7-1 -> 0.035

Sheet Balance Sheet
B2: Balance sheet
B3: Demo Co. (synthetic) · $mm · Source: SYNTHETIC DEMO DATA
C6: FY23A | D6: FY24A | E6: FY25A | F6: FY26E | G6: FY27E | H6: FY28E | I6: FY29E | J6: FY30E
B7: Cash | C7: 260 | D7: 280 | E7: 300 | F7: ='Cash Flow'!F17+'Cash Flow'!F18 -> 422.44762 | G7: ='Cash Flow'!G17+'Cash Flow'!G18 -> 576.2413 | H7: ='Cash Flow'!H17+'Cash Flow'!H18 -> 768.14278 | I7: ='Cash Flow'!I17+'Cash Flow'!I18 -> 997.7207 | J7: ='Cash Flow'!J17+'Cash Flow'!J18 -> 1264.1992
B8: Accounts receivable | C8: 540 | D8: 585 | E8: 620 | F8: ='Income Statement'!F7*Inputs!F$31/365 -> 655.89041 | G8: ='Income Statement'!G7*Inputs!G$31/365 -> 688.68493 | H8: ='Income Statement'!H7*Inputs!H$31/365 -> 719.67575 | I8: ='Income Statement'!I7*Inputs!I$31/365 -> 748.46278 | J8: ='Income Statement'!J7*Inputs!J$31/365 -> 774.65898
B9: Inventory | C9: 505 | D9: 535 | E9: 560 | F9: ='Income Statement'!F8*Inputs!F$37/365 -> 581.41952 | G9: ='Income Statement'!G8*Inputs!G$37/365 -> 610.4905 | H9: ='Income Statement'!H8*Inputs!H$37/365 -> 637.96257 | I9: ='Income Statement'!I8*Inputs!I$37/365 -> 663.48107 | J9: ='Income Statement'!J8*Inputs!J$37/365 -> 686.70291
B10: Other current assets | C10: 110 | D10: 115 | E10: 120 | F10: =E10 -> 120 | G10: =F10 -> 120 | H10: =G10 -> 120 | I10: =H10 -> 120 | J10: =I10 -> 120
B11: PP&E, net | C11: 1380 | D11: 1415 | E11: 1450 | F11: =E11+'Income Statement'!F7*Inputs!$C$54-'Income Statement'!F12 -> 1494.8875 | G11: =F11+'Income Statement'!G7*Inputs!$C$54-'Income Statement'!G12 -> 1542.0194 | H11: =G11+'Income Statement'!H7*Inputs!$C$54-'Income Statement'!H12 -> 1591.2722 | I11: =H11+'Income Statement'!I7*Inputs!$C$54-'Income Statement'!I12 -> 1642.4951 | J11: =I11+'Income Statement'!J7*Inputs!$C$54-'Income Statement'!J12 -> 1695.5108
B12: Goodwill & intangibles | C12: 900 | D12: 900 | E12: 900 | F12: =E12 -> 900 | G12: =F12 -> 900 | H12: =G12 -> 900 | I12: =H12 -> 900 | J12: =I12 -> 900
B13: Total assets | C13: =SUM(C7:C12) -> 3695 | D13: =SUM(D7:D12) -> 3830 | E13: =SUM(E7:E12) -> 3950 | F13: =SUM(F7:F12) -> 4174.645 | G13: =SUM(G7:G12) -> 4437.4361 | H13: =SUM(H7:H12) -> 4737.0533 | I13: =SUM(I7:I12) -> 5072.1597 | J13: =SUM(J7:J12) -> 5441.072
B15: Accounts payable | C15: 345 | D15: 362 | E15: 380 | F15: ='Income Statement'!F8*Inputs!F$43/365 -> 400.70805 | G15: ='Income Statement'!G8*Inputs!G$43/365 -> 420.74345 | H15: ='Income Statement'!H8*Inputs!H$43/365 -> 439.67691 | I15: ='Income Statement'!I8*Inputs!I$43/365 -> 457.26398 | J15: ='Income Statement'!J8*Inputs!J$43/365 -> 473.26822
B16: Other current liabilities | C16: 270 | D16: 280 | E16: 290 | F16: =E16 -> 290 | G16: =F16 -> 290 | H16: =G16 -> 290 | I16: =H16 -> 290 | J16: =I16 -> 290
B17: Revolver | C17: 0 | D17: 0 | E17: 0 | F17: =E17+'Cash Flow'!F18 -> 0 | G17: =F17+'Cash Flow'!G18 -> 0 | H17: =G17+'Cash Flow'!H18 -> 0 | I17: =H17+'Cash Flow'!I18 -> 0 | J17: =I17+'Cash Flow'!J18 -> 0
B18: Term debt | C18: 2200 | D18: 2050 | E18: 1900 | F18: =MAX(0,E18-Inputs!$C$51) -> 1750 | G18: =MAX(0,F18-Inputs!$C$51) -> 1600 | H18: =MAX(0,G18-Inputs!$C$51) -> 1450 | I18: =MAX(0,H18-Inputs!$C$51) -> 1300 | J18: =MAX(0,I18-Inputs!$C$51) -> 1150
B19: Other long-term liabilities | C19: 250 | D19: 255 | E19: 260 | F19: =E19 -> 260 | G19: =F19 -> 260 | H19: =G19 -> 260 | I19: =H19 -> 260 | J19: =I19 -> 260
B20: Total liabilities | C20: =SUM(C15:C19) -> 3065 | D20: =SUM(D15:D19) -> 2947 | E20: =SUM(E15:E19) -> 2830 | F20: =SUM(F15:F19) -> 2700.708 | G20: =SUM(G15:G19) -> 2570.7435 | H20: =SUM(H15:H19) -> 2439.6769 | I20: =SUM(I15:I19) -> 2307.264 | J20: =SUM(J15:J19) -> 2173.2682
B21: Equity | C21: 630 | D21: 883 | E21: 1120 | F21: =E21+'Income Statement'!F18-Inputs!$C$52 -> 1473.937 | G21: =F21+'Income Statement'!G18-Inputs!$C$52 -> 1866.6927 | H21: =G21+'Income Statement'!H18-Inputs!$C$52 -> 2297.3764 | I21: =H21+'Income Statement'!I18-Inputs!$C$52 -> 2764.8957 | J21: =I21+'Income Statement'!J18-Inputs!$C$52 -> 3267.8037
B22: Total liabilities & equity | C22: =C20+C21 -> 3695 | D22: =D20+D21 -> 3830 | E22: =E20+E21 -> 3950 | F22: =F20+F21 -> 4174.645 | G22: =G20+G21 -> 4437.4361 | H22: =H20+H21 -> 4737.0533 | I22: =I20+I21 -> 5072.1597 | J22: =J20+J21 -> 5441.072
B24: Check: assets − liabilities − equity | C24: =ROUND(C13-C22,6) -> 0 | D24: =ROUND(D13-D22,6) -> 0 | E24: =ROUND(E13-E22,6) -> 0 | F24: =ROUND(F13-F22,6) -> 0 | G24: =ROUND(G13-G22,6) -> 0 | H24: =ROUND(H13-H22,6) -> 0 | I24: =ROUND(I13-I22,6) -> 0 | J24: =ROUND(J13-J22,6) -> 0

Sheet Cash Flow
B2: Cash flow statement
B3: Demo Co. (synthetic) · $mm · Source: SYNTHETIC DEMO DATA
C6: FY23A | D6: FY24A | E6: FY25A | F6: FY26E | G6: FY27E | H6: FY28E | I6: FY29E | J6: FY30E
B7: Net income | F7: ='Income Statement'!F18 -> 503.937 | G7: ='Income Statement'!G18 -> 542.75566 | H7: ='Income Statement'!H18 -> 580.68372 | I7: ='Income Statement'!I18 -> 617.5193 | J7: ='Income Statement'!J18 -> 652.90807
B8: D&A | F8: ='Income Statement'!F12 -> 179.55 | G8: ='Income Statement'!G12 -> 188.5275 | H8: ='Income Statement'!H12 -> 197.01124 | I8: ='Income Statement'!I12 -> 204.89169 | J8: ='Income Statement'!J12 -> 212.0629
B9: (Increase) in receivables | F9: ='Balance Sheet'!E8-'Balance Sheet'!F8 -> -35.890411 | G9: ='Balance Sheet'!F8-'Balance Sheet'!G8 -> -32.794521 | H9: ='Balance Sheet'!G8-'Balance Sheet'!H8 -> -30.990822 | I9: ='Balance Sheet'!H8-'Balance Sheet'!I8 -> -28.78703 | J9: ='Balance Sheet'!I8-'Balance Sheet'!J8 -> -26.196197
B10: (Increase) in inventory | F10: ='Balance Sheet'!E9-'Balance Sheet'!F9 -> -21.419521 | G10: ='Balance Sheet'!F9-'Balance Sheet'!G9 -> -29.070976 | H10: ='Balance Sheet'!G9-'Balance Sheet'!H9 -> -27.472072 | I10: ='Balance Sheet'!H9-'Balance Sheet'!I9 -> -25.518503 | J10: ='Balance Sheet'!I9-'Balance Sheet'!J9 -> -23.221838
B11: Increase in payables | F11: ='Balance Sheet'!F15-'Balance Sheet'!E15 -> 20.708048 | G11: ='Balance Sheet'!G15-'Balance Sheet'!F15 -> 20.035402 | H11: ='Balance Sheet'!H15-'Balance Sheet'!G15 -> 18.933455 | I11: ='Balance Sheet'!I15-'Balance Sheet'!H15 -> 17.587076 | J11: ='Balance Sheet'!J15-'Balance Sheet'!I15 -> 16.004239
B12: Cash from operations | F12: =SUM(F7:F11) -> 646.88512 | G12: =SUM(G7:G11) -> 689.45306 | H12: =SUM(H7:H11) -> 738.16552 | I12: =SUM(I7:I11) -> 785.69253 | J12: =SUM(J7:J11) -> 831.55717
B13: Capex | F13: =-'Income Statement'!F7*Inputs!$C$54 -> -224.4375 | G13: =-'Income Statement'!G7*Inputs!$C$54 -> -235.65938 | H13: =-'Income Statement'!H7*Inputs!$C$54 -> -246.26405 | I13: =-'Income Statement'!I7*Inputs!$C$54 -> -256.11461 | J13: =-'Income Statement'!J7*Inputs!$C$54 -> -265.07862
B14: Cash from investing | F14: =F13 -> -224.4375 | G14: =G13 -> -235.65938 | H14: =H13 -> -246.26405 | I14: =I13 -> -256.11461 | J14: =J13 -> -265.07862
B15: Term debt repayment | F15: =-('Balance Sheet'!E18-'Balance Sheet'!F18) -> -150 | G15: =-('Balance Sheet'!F18-'Balance Sheet'!G18) -> -150 | H15: =-('Balance Sheet'!G18-'Balance Sheet'!H18) -> -150 | I15: =-('Balance Sheet'!H18-'Balance Sheet'!I18) -> -150 | J15: =-('Balance Sheet'!I18-'Balance Sheet'!J18) -> -150
B16: Dividends | F16: =-Inputs!$C$52 -> -150 | G16: =-Inputs!$C$52 -> -150 | H16: =-Inputs!$C$52 -> -150 | I16: =-Inputs!$C$52 -> -150 | J16: =-Inputs!$C$52 -> -150
B17: Cash before revolver | F17: ='Balance Sheet'!E7+F12+F14+F15+F16 -> 422.44762 | G17: ='Balance Sheet'!F7+G12+G14+G15+G16 -> 576.2413 | H17: ='Balance Sheet'!G7+H12+H14+H15+H16 -> 768.14278 | I17: ='Balance Sheet'!H7+I12+I14+I15+I16 -> 997.7207 | J17: ='Balance Sheet'!I7+J12+J14+J15+J16 -> 1264.1992
B18: Revolver draw / (repayment) | F18: =MAX(-'Balance Sheet'!E17,Inputs!$C$50-F17) -> 0 | G18: =MAX(-'Balance Sheet'!F17,Inputs!$C$50-G17) -> 0 | H18: =MAX(-'Balance Sheet'!G17,Inputs!$C$50-H17) -> 0 | I18: =MAX(-'Balance Sheet'!H17,Inputs!$C$50-I17) -> 0 | J18: =MAX(-'Balance Sheet'!I17,Inputs!$C$50-J17) -> 0
B19: Cash from financing | F19: =F15+F16+F18 -> -300 | G19: =G15+G16+G18 -> -300 | H19: =H15+H16+H18 -> -300 | I19: =I15+I16+I18 -> -300 | J19: =J15+J16+J18 -> -300
B20: Net change in cash | F20: =F12+F14+F19 -> 122.44762 | G20: =G12+G14+G19 -> 153.79369 | H20: =H12+H14+H19 -> 191.90148 | I20: =I12+I14+I19 -> 229.57792 | J20: =J12+J14+J19 -> 266.47855
B21: Beginning cash | F21: ='Balance Sheet'!E7 -> 300 | G21: ='Balance Sheet'!F7 -> 422.44762 | H21: ='Balance Sheet'!G7 -> 576.2413 | I21: ='Balance Sheet'!H7 -> 768.14278 | J21: ='Balance Sheet'!I7 -> 997.7207
B22: Ending cash | F22: =F21+F20 -> 422.44762 | G22: =G21+G20 -> 576.2413 | H22: =H21+H20 -> 768.14278 | I22: =I21+I20 -> 997.7207 | J22: =J21+J20 -> 1264.1992
B23: Check: ending cash vs balance sheet | F23: =ROUND(F22-'Balance Sheet'!F7,6) -> 0 | G23: =ROUND(G22-'Balance Sheet'!G7,6) -> 0 | H23: =ROUND(H22-'Balance Sheet'!H7,6) -> 0 | I23: =ROUND(I22-'Balance Sheet'!I7,6) -> 0 | J23: =ROUND(J22-'Balance Sheet'!J7,6) -> 0

Sheet Summary
B2: Summary: credit and cash flow (active scenario)
B3: Demo Co. (synthetic) · $mm · Source: SYNTHETIC DEMO DATA
B4: ="Active scenario: "&Inputs!$D$5 -> Active scenario: Base
C6: FY23A | D6: FY24A | E6: FY25A | F6: FY26E | G6: FY27E | H6: FY28E | I6: FY29E | J6: FY30E
B7: Revenue | C7: ='Income Statement'!C7 -> 4200 | D7: ='Income Statement'!D7 -> 4480 | E7: ='Income Statement'!E7 -> 4750 | F7: ='Income Statement'!F7 -> 4987.5 | G7: ='Income Statement'!G7 -> 5236.875 | H7: ='Income Statement'!H7 -> 5472.5344 | I7: ='Income Statement'!I7 -> 5691.4357 | J7: ='Income Statement'!J7 -> 5890.636
B8: EBITDA | C8: ='Income Statement'!C11 -> 735 | D8: ='Income Statement'!D11 -> 815.36 | E8: ='Income Statement'!E11 -> 883.5 | F8: ='Income Statement'!F11 -> 947.625 | G8: ='Income Statement'!G11 -> 995.00625 | H8: ='Income Statement'!H11 -> 1039.7815 | I8: ='Income Statement'!I11 -> 1081.3728 | J8: ='Income Statement'!J11 -> 1119.2208
B9: EBITDA margin | C9: ='Income Statement'!C11/'Income Statement'!C7 -> 0.175 | D9: ='Income Statement'!D11/'Income Statement'!D7 -> 0.182 | E9: ='Income Statement'!E11/'Income Statement'!E7 -> 0.186 | F9: ='Income Statement'!F11/'Income Statement'!F7 -> 0.19 | G9: ='Income Statement'!G11/'Income Statement'!G7 -> 0.19 | H9: ='Income Statement'!H11/'Income Statement'!H7 -> 0.19 | I9: ='Income Statement'!I11/'Income Statement'!I7 -> 0.19 | J9: ='Income Statement'!J11/'Income Statement'!J7 -> 0.19
B10: Free cash flow (CFO − capex) | F10: ='Cash Flow'!F12+'Cash Flow'!F13 -> 422.44762 | G10: ='Cash Flow'!G12+'Cash Flow'!G13 -> 453.79369 | H10: ='Cash Flow'!H12+'Cash Flow'!H13 -> 491.90148 | I10: ='Cash Flow'!I12+'Cash Flow'!I13 -> 529.57792 | J10: ='Cash Flow'!J12+'Cash Flow'!J13 -> 566.47855
B11: Net debt | C11: =('Balance Sheet'!C18+'Balance Sheet'!C17-'Balance Sheet'!C7) -> 1940 | D11: =('Balance Sheet'!D18+'Balance Sheet'!D17-'Balance Sheet'!D7) -> 1770 | E11: =('Balance Sheet'!E18+'Balance Sheet'!E17-'Balance Sheet'!E7) -> 1600 | F11: =('Balance Sheet'!F18+'Balance Sheet'!F17-'Balance Sheet'!F7) -> 1327.5524 | G11: =('Balance Sheet'!G18+'Balance Sheet'!G17-'Balance Sheet'!G7) -> 1023.7587 | H11: =('Balance Sheet'!H18+'Balance Sheet'!H17-'Balance Sheet'!H7) -> 681.85722 | I11: =('Balance Sheet'!I18+'Balance Sheet'!I17-'Balance Sheet'!I7) -> 302.2793 | J11: =('Balance Sheet'!J18+'Balance Sheet'!J17-'Balance Sheet'!J7) -> -114.19925
B12: Net debt / EBITDA | C12: =('Balance Sheet'!C18+'Balance Sheet'!C17-'Balance Sheet'!C7)/'Income Statement'!C11 -> 2.6394558 | D12: =('Balance Sheet'!D18+'Balance Sheet'!D17-'Balance Sheet'!D7)/'Income Statement'!D11 -> 2.1708203 | E12: =('Balance Sheet'!E18+'Balance Sheet'!E17-'Balance Sheet'!E7)/'Income Statement'!E11 -> 1.8109791 | F12: =('Balance Sheet'!F18+'Balance Sheet'!F17-'Balance Sheet'!F7)/'Income Statement'!F11 -> 1.4009259 | G12: =('Balance Sheet'!G18+'Balance Sheet'!G17-'Balance Sheet'!G7)/'Income Statement'!G11 -> 1.0288968 | H12: =('Balance Sheet'!H18+'Balance Sheet'!H17-'Balance Sheet'!H7)/'Income Statement'!H11 -> 0.6557697 | I12: =('Balance Sheet'!I18+'Balance Sheet'!I17-'Balance Sheet'!I7)/'Income Statement'!I11 -> 0.27953293 | J12: =('Balance Sheet'!J18+'Balance Sheet'!J17-'Balance Sheet'!J7)/'Income Statement'!J11 -> -0.1020346
B13: EBITDA / interest | C13: ='Income Statement'!C11/'Income Statement'!C14 -> 5.8333333 | D13: ='Income Statement'!D11/'Income Statement'!D14 -> 6.6289431 | E13: ='Income Statement'!E11/'Income Statement'!E14 -> 7.4872881 | F13: ='Income Statement'!F11/'Income Statement'!F14 -> 8.3125 | G13: ='Income Statement'!G11/'Income Statement'!G14 -> 9.47625 | H13: ='Income Statement'!H11/'Income Statement'!H14 -> 10.831058 | I13: ='Income Statement'!I11/'Income Statement'!I14 -> 12.429572 | J13: ='Income Statement'!J11/'Income Statement'!J14 -> 14.348985
B14: Revolver balance | C14: ='Balance Sheet'!C17 -> 0 | D14: ='Balance Sheet'!D17 -> 0 | E14: ='Balance Sheet'!E17 -> 0 | F14: ='Balance Sheet'!F17 -> 0 | G14: ='Balance Sheet'!G17 -> 0 | H14: ='Balance Sheet'!H17 -> 0 | I14: ='Balance Sheet'!I17 -> 0 | J14: ='Balance Sheet'!J17 -> 0
B15: Balance sheet check | C15: ='Balance Sheet'!C24 -> 0 | D15: ='Balance Sheet'!D24 -> 0 | E15: ='Balance Sheet'!E24 -> 0 | F15: ='Balance Sheet'!F24 -> 0 | G15: ='Balance Sheet'!G24 -> 0 | H15: ='Balance Sheet'!H24 -> 0 | I15: ='Balance Sheet'!I24 -> 0 | J15: ='Balance Sheet'!J24 -> 0
B16: Cash check | F16: ='Cash Flow'!F23 -> 0 | G16: ='Cash Flow'!G23 -> 0 | H16: ='Cash Flow'!H23 -> 0 | I16: ='Cash Flow'!I23 -> 0 | J16: ='Cash Flow'!J23 -> 0
